Workbook

Sheet CR Sales
A1: Brand | B1: SKU | C1: Product | D1: Quantity
A2: Grundfos | B2: 96501699-BIP66 | C2: Grundfos CR 15-3 3kW 2P Vertical multistage mounted on base with rubber mounts IP-66 Upgrade | D2: 6
A3: Grundfos | B3: 99247817-B | C3: Grundfos CRIE 15-3 3 kW IE3 IP-55 integral variable speed mounted on base with rubber mounts | D3: 6
A4: Grundfos | B4: 96500327BASE | C4: Grundfos CR 20-2 2.2kW 2P Vertical multistage mounted on base with rubber mounts | D4: 4
A5: Grundfos | B5: 96501698-BIP66 | C5: Grundfos CR 15-2 2.2kW 2P IP66 Vertical multistage mounted on base with rubber mounts | D5: 4
A6: Grundfos | B6: 99655815 | C6: CRE10-4 PV-A-A-E-HQQE 1x200-240 60 HZ | D6: 3
A7: Grundfos | B7: 92959623 | C7: Grundfos CR 10-4 1.5kW 240/1/50 Fixed speed vertical multistage pump IE3 IP-55 | D7: 2
A8: Grundfos | B8: 96516172 | C8: Grundfos CR 1-4 0.37kW 415V Vertical multistage pump | D8: 2
A9: Grundfos | B9: 96516173 | C9: Grundfos CR 1-5 0.37kW 415V Vertical multistage pump | D9: 2
A10: Grundfos | B10: 96121952-IP66 | C10: Grundfos CR 32-2-2 3kW 2P Vertical multistage pump. Motor upgraded to IP-66 for external installation. | D10: 2
A11: Grundfos | B11: 96500964DTBASE | C11: Grundfos CR 10-2 0.75kW 2P Vertical multistage mounted on base with rubber mounts and stainless steel drip tray | D11: 2
A12: Grundfos | B12: 96501697-BDT | C12: Grundfos CR 15-1 1.1kW 2P Vertical multistage mounted on base with SS drip tray & rubber mounts | D12: 2
A13: Grundfos | B13: 96501698-B | C13: Grundfos CR 15-2 2.2kW 2P Vertical multistage mounted on base with rubber mounts | D13: 2
A14: Grundfos | B14: 96501896-IP56 | C14: Grundfos CR 15-4 4kW Vertical Multistage + IP56 | D14: 2
A15: Grundfos | B15: 96516592DTBASE | C15: Grundfos CR 3-4 0.37kW 2P Vertical multistage mounted on base with rubber mounts and stainless steel drip tray | D15: 2
A16: Grundfos | B16: 96517037-B | C16: Grundfos CR 5-2 0.37kW 2P Vertical multistage mounted on base with rubber mounts | D16: 2
A17: Grundfos | B17: 96517039-B | C17: Grundfos CR 5-4 0.55kW 2P Vertical multistage mounted on base with rubber mounts | D17: 2
A18: Grundfos | B18: 96517039ISEIS-IP-56 | C18: Grundfos CR 5-4 0.55kW + IB + SEIS + IP-56 | D18: 2
A19: Grundfos | B19: 96520640DTBASE | C19: Grundfos CRN 1-4 0.37kW 415/3/50 | D19: 2
A20: Grundfos | B20: 92900972 | C20: Grundfos CR 1-7 0.37kW 240/1/50 Fixed speed vertical multistage pump IE3 IP-55 | D20: 1
A21: Grundfos | B21: 96122799 | C21: Grundfos CR 45-2 7.5kW IE3 IP-55 80mm DIN Flanged inline vertical multistage pump | D21: 1
A22: Grundfos | B22: 96511750 | C22: Grundfos CR 5-8 1.1kW 415V Vertical multistage pump | D22: 1
A23: Grundfos | B23: 96515647 | C23: Grundfos CR 1S-2 0.37kW Vertical multistage pump | D23: 1
A24: Grundfos | B24: 96515649 | C24: Grundfos CR 1S-3 0.37kW Vertical multistage pump | D24: 1
A25: Grundfos | B25: 99237436 | C25: CRE 10-3 2.2kW vertical multistage pump with integral variable speed drive | D25: 1
A26: Grundfos | B26: 99237443 | C26: CRE 15-1 1.5kW vertical multistage pump with integral variable speed drive | D26: 1
A27: Grundfos | B27: 99237456 | C27: CRE 20-2 inline vertical multistage pump with integral variable speed drive. | D27: 1
A28: Grundfos | B28: 99237528 | C28: CRE 45-2-1 11kW vertical multistage pump with integral variable speed drive | D28: 1
A29: Grundfos | B29: 96121952DTBASE | C29: Grundfos CR 32-2-2 3kW 2P Vertical multistage mounted on base with SS drip tray & rubber mounts | D29: 1
A30: Grundfos | B30: 96500966-BIP66 | C30: Grundfos CR 10-4 1.5kW 2P Vertical multistage mounted on base with rubber mounts IP-66 Upgrade | D30: 1
A31: Grundfos | B31: 96516977BASE | C31: Grundfos CR 5-4 0.55kW + BASE + RUBBER MOUNT | D31: 1

Sheet NBG BOM
A1: Item No | B1: Name | C1: kW | D1: Poles | E1: Inertia PN | F1: Inertia Size | G1: Standard Spring PN | H1: Standard Spring | I1: 50mm Static Spring PN | J1: 50mm Spring | K1: Qty Springs | L1: Pump List | M1: Pump Nett | N1: IP-56 List | O1: IP-56 Nett | P1: IP-66 List | Q1: IP-66 Nett | R1: Inertia Nett | S1: Crossbar Nett | T1: Standard Spring Nett | U1: Total Standard Spring Nett | V1: 50mm Spring Nett | W1: Total 50mm Spring | X1: 24/25 Pump List | Y1: 24/25 Pump Nett | Z1: Total Cost | AA1: Total Sell | AB1: Margin
A2: 99801136 | B2: NBG 125-100-160/167 | C2: 22 | D2: 2 | E2: 98327389 | F2: 1200 x 800 x 200 | G2: 91338018 | H2: CLM-97 | I2: 93176762 | J2: CDM-521 | K2: 4 | L2: 9151 | M2: 4575.5 | R2: 663.42 | S2: 284.76 | T2: 170.3 | U2: 681.2 | V2: 668.94 | W2: 2675.76 | X2: 9151 | Y2: 4575.5 | Z2: 5920.12 | AA2: 7264 | AB2: 0.815
A3: 99801135 | B3: NBG 125-100-160/160-154 | C3: 18.5 | D3: 2 | E3: 98327389 | F3: 1200 x 800 x 200 | G3: 91338018 | H3: CLM-97 | I3: 93176762 | J3: CDM-521 | K3: 4 | L3: 8227 | M3: 4113.5 | R3: 663.42 | S3: 284.76 | T3: 170.3 | U3: 681.2 | V3: 668.94 | W3: 2675.76 | X3: 8227 | Y3: 4113.5 | Z3: 5458.12 | AA3: 6698
A4: 99796408 | B4: NBG 50-32-160/163 | C4: 4 | D4: 2 | E4: 98336369 | F4: 800 x 630 x 125 | G4: 92932672 | H4: CSM-14 | I4: 93176749 | J4: CWDM-36 | K4: 4 | L4: 4233 | M4: 2116.5 | P4: 380 | Q4: 190 | R4: 565.52 | S4: 284.76 | T4: 59.52 | U4: 238.08 | V4: 288.58 | W4: 1154.32 | X4: 4233 | Y4: 2116.5 | Z4: 2920.1 | AA4: 3583
A5: 99801330 | B5: NBG 125-80-200/179 | C5: 3 | D5: 4 | E5: 98327382 | F5: 950 x 720 x 150 | G5: 91338157 | H5: CSM-17 | I5: 93176761 | J5: CWDM-37 | K5: 4 | L5: 5455 | M5: 2727.5 | R5: 532.03 | S5: 284.76 | T5: 59.52 | U5: 238.08 | V5: 288.59 | W5: 1154.36 | X5: 5455 | Y5: 2727.5 | Z5: 3497.61 | AA5: 4292
A6: 99801137 | B6: NBG 125-100-160/176 | C6: 30 | D6: 4 | E6: 99051550 | F6: 1500 x 800 x 225 | G6: 91338019 | H6: CLM-98 | J6: CDM-53 | K6: 4 | L6: 11109 | M6: 5554.5 | R6: 741.99 | S6: 284.76 | T6: 170.3 | U6: 681.2 | V6: 668.94 | W6: 2675.76 | X6: 11109 | Y6: 5554.5 | Z6: 6977.69 | AA6: 8562
A7: 99801329 | B7: NBG 125-80-200/164 | C7: 2.2 | D7: 4 | E7: 98327382 | F7: 950 x 720 x 150 | G7: 92932673 | H7: CSM-16 | I7: 93176761 | J7: CWDM-37 | K7: 4 | L7: 5346 | M7: 2673 | R7: 532.03 | S7: 284.76 | T7: 59.52 | U7: 238.08 | V7: 288.59 | W7: 1154.36 | X7: 5346 | Y7: 2673 | Z7: 3443.11 | AA7: 4225
A8: 99801142 | B8: NBG 125-100-250/205 | C8: 55 | D8: 2 | F8: #N/A | G8: #N/A | H8: #N/A | I8: #N/A | J8: #N/A | L8: 17256 | M8: 8628 | R8: #REF! | S8: $ - | T8: #N/A | U8: #N/A | V8: #N/A | W8: #N/A | X8: 17256 | Y8: 8628 | Z8: 1 | AA8: 2
A9: 99801331 | B9: NBG 125-80-200/196 | C9: 4 | D9: 4 | E9: 98327382 | F9: 950 x 720 x 150 | G9: 91338157 | H9: CSM-17 | I9: 93176761 | J9: CWDM-37 | K9: 4 | L9: 5748 | M9: 2874 | R9: 532.03 | S9: 284.76 | T9: 59.52 | U9: 238.08 | V9: 288.59 | W9: 1154.36 | X9: 5748 | Y9: 2874 | Z9: 3644.11 | AA9: 4472
A10: 99801348 | B10: NBG 125-100-160/169 | C10: 3 | D10: 4 | E10: 98327389 | F10: 1200 x 800 x 200 | G10: 91338016 | H10: CLM-96 | I10: 93176760 | J10: CWDM-38 | K10: 4 | L10: 5144 | M10: 2572 | R10: 663.42 | S10: 284.76 | T10: 135.26 | U10: 541.04 | V10: 288.61 | W10: 1154.44 | X10: 5144 | Y10: 2572 | Z10: 3776.46 | AA10: 4634
A11: 99801347 | B11: NBG 125-100-160/160-140 | C11: 2.2 | D11: 4 | E11: 98327382 | F11: 950 x 720 x 150 | G11: 92932673 | H11: CSM-16 | I11: 93176761 | J11: CWDM-37 | K11: 4 | L11: 5035 | M11: 2517.5 | R11: 532.03 | S11: 284.76 | T11: 59.52 | U11: 238.08 | V11: 288.59 | W11: 1154.36 | X11: 5035 | Y11: 2517.5 | Z11: 3287.61 | AA11: 4034
A12: 99801144 | B12: NBG 125-100-250/242 | C12: 90 | D12: 2 | E12: TBA | F12: 2100 x 1000 x 300 | G12: 91338021 | H12: CLM-100 | J12: CDM-55 | K12: 6 | L12: 22297 | M12: 11148.5 | R12: 1100 | S12: 427.14 | T12: 170.3 | U12: 1021.8 | V12: 717.41 | W12: 4304.46 | X12: 22297 | Y12: 11148.5 | Z12: 13270.3 | AA12: 16283
A13: 99801349 | B13: NBG 125-100-160/176 | C13: 4 | D13: 4 | E13: 98327389 | F13: 1200 x 800 x 200 | G13: 91338016 | H13: CLM-96 | I13: 93176760 | J13: CWDM-38 | K13: 4 | L13: 5437 | M13: 2718.5 | R13: 663.42 | S13: 284.76 | T13: 135.26 | U13: 541.04 | V13: 288.61 | W13: 1154.44 | X13: 5437 | Y13: 2718.5 | Z13: 3922.96 | AA13: 4814
A14: 99801122 | B14: NBG 125-80-160/167 | C14: 22 | D14: 2 | E14: 98327389 | F14: 1200 x 800 x 200 | G14: 91338018 | H14: CLM-97 | I14: 93176762 | J14: CDM-521 | K14: 4 | L14: 8955 | M14: 4477.5 | N14: 866 | O14: 433 | R14: 663.42 | S14: 284.76 | T14: 170.3 | U14: 681.2 | V14: 668.94 | W14: 2675.76 | X14: 8955 | Y14: 4477.5 | Z14: 5822.12 | AA14: 7144
A15: 99801143 | B15: NBG 125-100-250/229 | C15: 75 | D15: 2 | E15: TBA | F15: 2100 x 1000 x 300 | G15: 91338020 | H15: CLM-99 | J15: CDM-531 | K15: 6 | L15: 20550 | M15: 10275 | R15: 1100 | S15: 427.14 | T15: 170.3 | U15: 1021.8 | V15: 717.41 | W15: 4304.46 | X15: 20550 | Y15: 10275 | Z15: 12396.8 | AA15: 15211
A16: 99801116 | B16: NBG 100-80-160/143 | C16: 7.5 | D16: 2 | E16: 98327382 | F16: 950 x 720 x 150 | G16: 91338157 | H16: CSM-17 | I16: 93176761 | J16: CWDM-37 | K16: 4 | L16: 5687 | M16: 2843.5 | N16: 1209.33 | O16: 604.67 | P16: 2102.22 | Q16: 1051.11 | R16: 532.03 | S16: 284.76 | T16: 59.52 | U16: 238.08 | V16: 288.59 | W16: 1154.36 | X16: 5687 | Y16: 2843.5 | Z16: 3613.61 | AA16: 4434
A17: 99801332 | B17: NBG 125-80-200/214 | C17: 5.5 | D17: 4 | E17: 92513065 | F17: 1100 x 800 x 150 | G17: 91338157 | H17: CSM-17 | I17: 93176761 | J17: CWDM-37 | K17: 4 | L17: 6465 | M17: 3232.5 | R17: 610.6 | S17: 284.76 | T17: 59.52 | U17: 238.08 | V17: 288.59 | W17: 1154.36 | X17: 6465 | Y17: 3232.5 | Z17: 4081.18 | AA17: 5008
A18: 99801334 | B18: NBG 125-80-200/222 | C18: 7.5 | D18: 4 | E18: 98327389 | F18: 1200 x 800 x 200 | G18: 91338018 | H18: CLM-97 | I18: 93176762 | J18: CDM-521 | K18: 4 | L18: 7040 | M18: 3520 | R18: 663.42 | S18: 284.76 | T18: 170.3 | U18: 681.2 | V18: 668.94 | W18: 2675.76 | X18: 7040 | Y18: 3520 | Z18: 4864.62 | AA18: 5969
A19: 99801395 | B19: NBG 200-150-400/343 | C19: 55 | D19: 4 | E19: TBA | F19: 2100 x 1000 x 300 | G19: 91338020 | H19: CLM-99 | J19: CDM-531 | K19: 6 | L19: 27708 | M19: 13854 | R19: 1100 | S19: 427.14 | T19: 170.3 | U19: 1021.8 | V19: 717.41 | W19: 4304.46 | X19: 27708 | Y19: 13854 | Z19: 15975.8 | AA19: 19603
A20: 99801320 | B20: NBG 100-80-160/149 | C20: 1.1 | D20: 4 | E20: 98336369 | F20: 800 x 630 x 125 | G20: 92932672 | H20: CSM-14 | I20: 93176749 | J20: CWDM-36 | K20: 4 | L20: 3821 | M20: 1910.5 | R20: 565.52 | S20: 284.76 | T20: 59.52 | U20: 238.08 | V20: 288.58 | W20: 1154.32 | X20: 3821 | Y20: 1910.5 | Z20: 2714.1 | AA20: 3331
A21: 99801123 | B21: NBG 125-80-160/177 | C21: 30 | D21: 2 | E21: 99051550 | F21: 1500 x 800 x 225 | G21: 91338019 | H21: CLM-98 | J21: CDM-53 | K21: 4 | L21: 11151 | M21: 5575.5 | R21: 741.99 | S21: 284.76 | T21: 170.3 | U21: 681.2 | V21: 668.94 | W21: 2675.76 | X21: 11151 | Y21: 5575.5 | Z21: 6998.69 | AA21: 8588
A22: 99801321 | B22: NBG 100-80-160/165 | C22: 1.5 | D22: 4 | E22: 98336369 | F22: 800 x 630 x 125 | G22: 92932672 | H22: CSM-14 | I22: 93176749 | J22: CWDM-36 | K22: 4 | L22: 3862 | M22: 1931 | R22: 565.52 | S22: 284.76 | T22: 59.52 | U22: 238.08 | V22: 288.58 | W22: 1154.32 | X22: 3862 | Y22: 1931 | Z22: 2734.6 | AA22: 3356
A23: 99801276 | B23: NBG 50-32-200/216 | C23: 1.1 | D23: 4 | E23: 98336369 | F23: 800 x 630 x 125 | G23: 92932672 | H23: CSM-14 | I23: 93176749 | J23: CWDM-36 | K23: 4 | L23: 3589 | M23: 1794.5 | R23: 565.52 | S23: 284.76 | T23: 59.52 | U23: 238.08 | V23: 288.58 | W23: 1154.32 | X23: 3589 | Y23: 1794.5 | Z23: 2598.1 | AA23: 3188
A24: 99801328 | B24: NBG 125-80-160/177 | C24: 4 | D24: 4 | E24: 98327389 | F24: 1200 x 800 x 200 | G24: 91338016 | H24: CLM-96 | I24: 93176760 | J24: CWDM-38 | K24: 4 | L24: 4822 | M24: 2411 | R24: 663.42 | S24: 284.76 | T24: 135.26 | U24: 541.04 | V24: 288.61 | W24: 1154.44 | X24: 4822 | Y24: 2411 | Z24: 3615.46 | AA24: 4437
A25: 99801327 | B25: NBG 125-80-160/175 | C25: 3 | D25: 4 | E25: 98327382 | F25: 950 x 720 x 150 | G25: 92932673 | H25: CSM-16 | I25: 93176761 | J25: CWDM-37 | K25: 4 | L25: 4542 | M25: 2271 | R25: 532.03 | S25: 284.76 | T25: 59.52 | U25: 238.08 | V25: 288.59 | W25: 1154.36 | X25: 4542 | Y25: 2271 | Z25: 3041.11 | AA25: 3732
A26: 99801128 | B26: NBG 125-80-200/222 | C26: 55 | D26: 4 | E26: 98299752 | F26: 1500 x 900 x 300 | G26: 91338021 | H26: CLM-100 | J26: CDM-55 | K26: 4 | L26: 17320 | M26: 8660 | R26: 824.44 | S26: 284.76 | T26: 170.3 | U26: 681.2 | V26: 717.41 | W26: 2869.64 | X26: 17320 | Y26: 8660 | Z26: 10165.64 | AA26: 12474
A27: 99801325 | B27: NBG 125-80-160/146 | C27: 1.5 | D27: 4 | E27: 98336369 | F27: 800 x 630 x 125 | G27: 92932672 | H27: CSM-14 | I27: 93176749 | J27: CWDM-36 | K27: 4 | L27: 4250 | M27: 2125 | R27: 565.52 | S27: 284.76 | T27: 59.52 | U27: 238.08 | V27: 288.58 | W27: 1154.32 | X27: 4250 | Y27: 2125 | Z27: 2928.6 | AA27: 3594
A28: 99801272 | B28: NBG 50-32-160/172 | C28: 0.55 | D28: 4 | E28: 98336369 | F28: 800 x 630 x 125 | G28: 92932672 | H28: CSM-14 | I28: 93176749 | J28: CWDM-36 | K28: 4 | L28: 3189 | M28: 1594.5 | R28: 565.52 | S28: 284.76 | T28: 59.52 | U28: 238.08 | V28: 288.58 | W28: 1154.32 | X28: 3189 | Y28: 1594.5 | Z28: 2398.1 | AA28: 2943
A29: 99801326 | B29: NBG 125-80-160/161 | C29: 2.2 | D29: 4 | E29: 92513065 | F29: 1100 x 800 x 150 | G29: 92932673 | H29: CSM-16 | I29: 93176761 | J29: CWDM-37 | K29: 4 | L29: 4445 | M29: 2222.5 | R29: 610.6 | S29: 284.76 | T29: 59.52 | U29: 238.08 | V29: 288.59 | W29: 1154.36 | X29: 4445 | Y29: 2222.5 | Z29: 3071.18 | AA29: 3769
A30: 99801275 | B30: NBG 50-32-200/197 | C30: 0.75 | D30: 4 | E30: 98336369 | F30: 800 x 630 x 125 | G30: 92932672 | H30: CSM-14 | I30: 93176749 | J30: CWDM-36 | K30: 4 | L30: 3520 | M30: 1760 | R30: 565.52 | S30: 284.76 | T30: 59.52 | U30: 238.08 | V30: 288.58 | W30: 1154.32 | X30: 3520 | Y30: 1760 | Z30: 2563.6 | AA30: 3146
A31: 99801289 | B31: NBG 65-50-160/162 | C31: 0.75 | D31: 4 | E31: 98336369 | F31: 800 x 630 x 125 | G31: 92932672 | H31: CSM-14 | I31: 93176749 | J31: CWDM-36 | K31: 4 | L31: 3542 | M31: 1771 | R31: 565.52 | S31: 284.76 | T31: 59.52 | U31: 238.08 | V31: 288.58 | W31: 1154.32 | X31: 3542 | Y31: 1771 | Z31: 2574.6 | AA31: 3160
A32: 99801345 | B32: NBG 125-80-400/419 | C32: 37 | D32: 4 | E32: 98299752 | F32: 1500 x 900 x 300 | G32: 91338021 | H32: CLM-100 | J32: CDM-55 | K32: 4 | L32: 19642 | M32: 9821 | N32: 2065.75 | O32: 1032.88 | P32: 4916.58 | Q32: 2458.29 | R32: 824.44 | S32: 284.76 | T32: 170.3 | U32: 681.2 | V32: 717.41 | W32: 2869.64 | X32: 19642 | Y32: 9821 | Z32: 11326.64 | AA32: 13898
A33: 99801323 | B33: NBG 100-80-160/177 | C33: 2.2 | D33: 4 | E33: 92513065 | F33: 1100 x 800 x 150 | G33: 92932673 | H33: CSM-16 | I33: 93176761 | J33: CWDM-37 | K33: 4 | L33: 4057 | M33: 2028.5 | R33: 610.6 | S33: 284.76 | T33: 59.52 | U33: 238.08 | V33: 288.59 | W33: 1154.36 | X33: 4057 | Y33: 2028.5 | Z33: 2877.18 | AA33: 3531
A34: 99796406 | B34: NBG 50-32-160/139 | C34: 2.2 | D34: 2 | E34: 98336369 | F34: 800 x 630 x 125 | G34: 92932672 | H34: CSM-14 | I34: 93176749 | J34: CWDM-36 | K34: 4 | L34: 3552 | M34: 1776 | R34: 565.52 | S34: 284.76 | T34: 59.52 | U34: 238.08 | V34: 288.58 | W34: 1154.32 | X34: 3552 | Y34: 1776 | Z34: 2579.6 | AA34: 3166
A35: 99801311 | B35: NBG 100-65-250/215 | C35: 3 | D35: 4 | E35: 98327382 | F35: 950 x 720 x 150 | G35: 91338157 | H35: CSM-17 | I35: 93176761 | J35: CWDM-37 | K35: 4 | L35: 5543 | M35: 2771.5 | R35: 532.03 | S35: 284.76 | T35: 59.52 | U35: 238.08 | V35: 288.59 | W35: 1154.36 | X35: 5543 | Y35: 2771.5 | Z35: 3541.61 | AA35: 4346
A36: 99801146 | B36: NBG 150-125-200/196-166 | C36: 55 | D36: 2 | E36: TBA | F36: 2100 x 1000 x 300 | G36: 91338020 | H36: CLM-99 | J36: CDM-531 | K36: 6 | L36: 16250 | M36: 8125 | R36: 1100 | S36: 427.14 | T36: 170.3 | U36: 1021.8 | V36: 717.41 | W36: 4304.46 | X36: 16250 | Y36: 8125 | Z36: 10246.8 | AA36: 12573
A37: 99801290 | B37: NBG 65-50-160/177 | C37: 1.1 | D37: 2 | E37: 98336369 | F37: 800 x 630 x 125 | G37: 92932672 | H37: CSM-14 | I37: 93176749 | J37: CWDM-36 | K37: 4 | L37: 3669 | M37: 1834.5 | R37: 565.52 | S37: 284.76 | T37: 59.52 | U37: 238.08 | V37: 288.58 | W37: 1154.32 | X37: 3669 | Y37: 1834.5 | Z37: 2638.1 | AA37: 3237
A38: 99801365 | B38: NBG 150-125-200/196-180 | C38: 7.5 | D38: 4 | E38: 98327389 | F38: 1200 x 800 x 200 | G38: 91338018 | H38: CLM-97 | I38: 93176762 | J38: CDM-521 | K38: 4 | L38: 7763 | M38: 3881.5 | R38: 663.42 | S38: 284.76 | T38: 170.3 | U38: 681.2 | V38: 668.94 | W38: 2675.76 | X38: 7763 | Y38: 3881.5 | Z38: 5226.12 | AA38: 6413
A39: 99801273 | B39: NBG 50-32-160/173 | C39: 0.75 | D39: 4 | E39: 98336369 | F39: 800 x 630 x 125 | G39: 92932672 | H39: CSM-14 | I39: 93176749 | J39: CWDM-36 | K39: 4 | L39: 3326 | M39: 1663 | R39: 565.52 | S39: 284.76 | T39: 59.52 | U39: 238.08 | V39: 288.58 | W39: 1154.32 | X39: 3326 | Y39: 1663 | Z39: 2466.6 | AA39: 3027
A40: 99801364 | B40: NBG 150-125-200/176-154 | C40: 5.5 | D40: 4 | E40: 92513065 | F40: 1100 x 800 x 150 | G40: 91338016 | H40: CLM-96 | I40: 93176760 | J40: CWDM-38 | K40: 4 | L40: 7308 | M40: 3654 | R40: 610.6 | S40: 284.76 | T40: 135.26 | U40: 541.04 | V40: 288.61 | W40: 1154.44 | X40: 7308 | Y40: 3654 | Z40: 4805.64 | AA40: 5897
...

Sheet NK BOM
A1: Item No | B1: Name | C1: kW | D1: Poles | E1: Inertia PN | F1: Inertia Size | G1: Std Spring PN | H1: Standard Spring | I1: 50mm Static Spring PN | J1: 50mm Spring | K1: Qty Springs | L1: Pump List | M1: Pump Nett | N1: IP-56 List | O1: IP-56 Nett | P1: IP-66 List | Q1: IP-66 Nett | R1: Inertia Nett | S1: Crossbar Nett | T1: Standard Spring Nett | U1: Total Standard Spring Nett | V1: 50mm Spring Nett | W1: Total 50mm Spring | X1: IE4
A2: 93030793 | B2: NK 150-280/273 | C2: 30 | D2: 4 | E2: 91338088 | F2: 1700 x 810 x 200 | G2: 91338019 | H2: CLM-98 | K2: 4 | L2: 13609.67 | M2: =L2/2 -> 6804.835 | R2: =VLOOKUP(E2,'Inertia Bases 2025'!$A:$H,8,0) -> 547.49 | T2: =VLOOKUP(G2,'Seismic Springs 2025'!$A:$I,9,0) -> 170.3 | U2: =T2*K2 -> 681.2
A3: 93030794 | B3: NK 100-280/240 | C3: 11 | D3: 4 | E3: 99051549 | F3: 1450 x 800 x 200 | G3: 91338018 | H3: CLM-97 | K3: 4 | L3: 10146.19 | M3: =L3/2 -> 5073.095 | R3: =VLOOKUP(E3,'Inertia Bases 2025'!$A:$H,8,0) -> 525.59 | T3: =VLOOKUP(G3,'Seismic Springs 2025'!$A:$I,9,0) -> 170.3 | U3: =T3*K3 -> 681.2
A4: 93030795 | B4: NK 125-380/307 | C4: 37 | D4: 4 | L4: 17265.15 | M4: =L4/2 -> 8632.575 | R4: =VLOOKUP(E4,'Inertia Bases 2025'!$A:$H,8,0) -> #N/A | T4: =VLOOKUP(G4,'Seismic Springs 2025'!$A:$I,9,0) -> #N/A | U4: =T4*K4 -> #N/A
A5: 93030796 | B5: NK 150-300/289 | C5: 30 | D5: 4 | E5: 92792038 | F5: 1700 x 900 x 200 | G5: 91338020 | H5: CLM-99 | K5: 4 | L5: 14226.58 | M5: =L5/2 -> 7113.29 | R5: =VLOOKUP(E5,'Inertia Bases 2025'!$A:$H,8,0) -> 780.65 | T5: =VLOOKUP(G5,'Seismic Springs 2025'!$A:$I,9,0) -> 170.3 | U5: =T5*K5 -> 681.2
A6: 93030797 | B6: NK 200-350/307 | C6: 55 | D6: 4 | E6: TBA-5 | F6: 1900 x 1200 x 250 | G6: 91338020 | H6: CLM-99 | K6: 6 | L6: 25256.92 | M6: =L6/2 -> 12628.46 | R6: =VLOOKUP(E6,'Inertia Bases 2025'!$A:$H,8,0) -> 1550 | T6: =VLOOKUP(G6,'Seismic Springs 2025'!$A:$I,9,0) -> 170.3 | U6: =T6*K6 -> 1021.8
A7: 93030798 | B7: NK 125-350/289 | C7: 22 | D7: 4 | E7: 91338088 | F7: 1700 x 810 x 200 | G7: 91338019 | H7: CLM-98 | K7: 4 | L7: 12765.38 | M7: =L7/2 -> 6382.69 | R7: =VLOOKUP(E7,'Inertia Bases 2025'!$A:$H,8,0) -> 547.49 | T7: =VLOOKUP(G7,'Seismic Springs 2025'!$A:$I,9,0) -> 170.3 | U7: =T7*K7 -> 681.2
A8: 93030799 | B8: NK 125-350/319 | C8: 30 | D8: 4 | E8: 91338088 | F8: 1700 x 810 x 200 | G8: 91338019 | H8: CLM-98 | K8: 4 | L8: 14899.28 | M8: =L8/2 -> 7449.64 | R8: =VLOOKUP(E8,'Inertia Bases 2025'!$A:$H,8,0) -> 547.49 | T8: =VLOOKUP(G8,'Seismic Springs 2025'!$A:$I,9,0) -> 170.3 | U8: =T8*K8 -> 681.2
A9: 93055390 | B9: NK 40-180/176 | C9: 11 | D9: 2 | L9: 6147.48 | M9: =L9/2 -> 3073.74 | R9: =VLOOKUP(E9,'Inertia Bases 2025'!$A:$H,8,0) -> #N/A | T9: =VLOOKUP(G9,'Seismic Springs 2025'!$A:$I,9,0) -> #N/A | U9: =T9*K9 -> #N/A
A10: 93055392 | B10: NK 40-180/173 | C10: 7.5 | D10: 2 | E10: 91338257 | F10: 1200 x 650 x 150 | G10: 92932673 | H10: CSM-16 | K10: 4 | L10: 5223.83 | M10: =L10/2 -> 2611.915 | R10: =VLOOKUP(E10,'Inertia Bases 2025'!$A:$H,8,0) -> 653.11 | T10: =VLOOKUP(G10,'Seismic Springs 2025'!$A:$I,9,0) -> 66.3 | U10: =T10*K10 -> 265.2
A11: 93055393 | B11: NK 40-180/155 | C11: 5.5 | D11: 2 | L11: 4934.38 | M11: =L11/2 -> 2467.19 | R11: =VLOOKUP(E11,'Inertia Bases 2025'!$A:$H,8,0) -> #N/A | T11: =VLOOKUP(G11,'Seismic Springs 2025'!$A:$I,9,0) -> #N/A | U11: =T11*K11 -> #N/A
A12: 93055394 | B12: NK 40-180/140 | C12: 4 | D12: 2 | E12: 92513065 | F12: 1100 x 800 x 150 | G12: 92932673 | H12: CSM-16 | K12: 4 | L12: 4552.89 | M12: =L12/2 -> 2276.445 | R12: =VLOOKUP(E12,'Inertia Bases 2025'!$A:$H,8,0) -> 610.6 | T12: =VLOOKUP(G12,'Seismic Springs 2025'!$A:$I,9,0) -> 66.3 | U12: =T12*K12 -> 265.2
A13: 93055395 | B13: NK 40-180/125 | C13: 3 | D13: 2 | L13: 4304.53 | M13: =L13/2 -> 2152.265 | R13: =VLOOKUP(E13,'Inertia Bases 2025'!$A:$H,8,0) -> #N/A | T13: =VLOOKUP(G13,'Seismic Springs 2025'!$A:$I,9,0) -> #N/A | U13: =T13*K13 -> #N/A
A14: 93055396 | B14: NK 40-180/112 | C14: 2.2 | D14: 2 | L14: 4004.36 | M14: =L14/2 -> 2002.18 | R14: =VLOOKUP(E14,'Inertia Bases 2025'!$A:$H,8,0) -> #N/A | T14: =VLOOKUP(G14,'Seismic Springs 2025'!$A:$I,9,0) -> #N/A | U14: =T14*K14 -> #N/A
A15: 93055397 | B15: NK 40-180/176 | C15: 1.1 | D15: 4 | L15: 3942.55 | M15: =L15/2 -> 1971.275 | R15: =VLOOKUP(E15,'Inertia Bases 2025'!$A:$H,8,0) -> #N/A | T15: =VLOOKUP(G15,'Seismic Springs 2025'!$A:$I,9,0) -> #N/A | U15: =T15*K15 -> #N/A
A16: 93055398 | B16: NK 40-180/162 | C16: 0.75 | D16: 4 | L16: 3744.24 | M16: =L16/2 -> 1872.12 | R16: =VLOOKUP(E16,'Inertia Bases 2025'!$A:$H,8,0) -> #N/A | T16: =VLOOKUP(G16,'Seismic Springs 2025'!$A:$I,9,0) -> #N/A | U16: =T16*K16 -> #N/A
A17: 93055399 | B17: NK 40-180/145 | C17: 0.55 | D17: 4 | L17: 3671.32 | M17: =L17/2 -> 1835.66 | R17: =VLOOKUP(E17,'Inertia Bases 2025'!$A:$H,8,0) -> #N/A | T17: =VLOOKUP(G17,'Seismic Springs 2025'!$A:$I,9,0) -> #N/A | U17: =T17*K17 -> #N/A
A18: 93055400 | B18: NK 40-180/130 | C18: 0.37 | D18: 4 | L18: 3433.98 | M18: =L18/2 -> 1716.99 | R18: =VLOOKUP(E18,'Inertia Bases 2025'!$A:$H,8,0) -> #N/A | T18: =VLOOKUP(G18,'Seismic Springs 2025'!$A:$I,9,0) -> #N/A | U18: =T18*K18 -> #N/A
A19: 93055401 | B19: NK 40-220/250 | C19: 18.5 | D19: 2 | L19: 7133.1 | M19: =L19/2 -> 3566.55 | R19: =VLOOKUP(E19,'Inertia Bases 2025'!$A:$H,8,0) -> #N/A | T19: =VLOOKUP(G19,'Seismic Springs 2025'!$A:$I,9,0) -> #N/A | U19: =T19*K19 -> #N/A
A20: 93055402 | B20: NK 40-220/244 | C20: 15 | D20: 2 | L20: 6876.54 | M20: =L20/2 -> 3438.27 | R20: =VLOOKUP(E20,'Inertia Bases 2025'!$A:$H,8,0) -> #N/A | T20: =VLOOKUP(G20,'Seismic Springs 2025'!$A:$I,9,0) -> #N/A | U20: =T20*K20 -> #N/A
A21: 93055403 | B21: NK 40-220/212 | C21: 11 | D21: 2 | E21: 91338087 | F21: 1320 x 740 x 125 | G21: 91338157 | H21: CSM-17 | K21: 4 | L21: 6633.58 | M21: =L21/2 -> 3316.79 | R21: =VLOOKUP(E21,'Inertia Bases 2025'!$A:$H,8,0) -> 541.04 | T21: =VLOOKUP(G21,'Seismic Springs 2025'!$A:$I,9,0) -> 66.3 | U21: =T21*K21 -> 265.2
A22: 93055404 | B22: NK 40-220/192 | C22: 7.5 | D22: 2 | L22: 5598.53 | M22: =L22/2 -> 2799.265 | R22: =VLOOKUP(E22,'Inertia Bases 2025'!$A:$H,8,0) -> #N/A | T22: =VLOOKUP(G22,'Seismic Springs 2025'!$A:$I,9,0) -> #N/A | U22: =T22*K22 -> #N/A
A23: 93055405 | B23: NK 40-220/172 | C23: 5.5 | D23: 2 | L23: 5320.18 | M23: =L23/2 -> 2660.09 | R23: =VLOOKUP(E23,'Inertia Bases 2025'!$A:$H,8,0) -> #N/A | T23: =VLOOKUP(G23,'Seismic Springs 2025'!$A:$I,9,0) -> #N/A | U23: =T23*K23 -> #N/A
A24: 93055406 | B24: NK 40-220/250 | C24: 2.2 | D24: 4 | L24: 4748.32 | M24: =L24/2 -> 2374.16 | R24: =VLOOKUP(E24,'Inertia Bases 2025'!$A:$H,8,0) -> #N/A | T24: =VLOOKUP(G24,'Seismic Springs 2025'!$A:$I,9,0) -> #N/A | U24: =T24*K24 -> #N/A
A25: 93055407 | B25: NK 40-220/218 | C25: 1.5 | D25: 4 | L25: 4491.34 | M25: =L25/2 -> 2245.67 | R25: =VLOOKUP(E25,'Inertia Bases 2025'!$A:$H,8,0) -> #N/A | T25: =VLOOKUP(G25,'Seismic Springs 2025'!$A:$I,9,0) -> #N/A | U25: =T25*K25 -> #N/A
A26: 93055408 | B26: NK 40-220/200 | C26: 1.1 | D26: 4 | L26: 4436.06 | M26: =L26/2 -> 2218.03 | R26: =VLOOKUP(E26,'Inertia Bases 2025'!$A:$H,8,0) -> #N/A | T26: =VLOOKUP(G26,'Seismic Springs 2025'!$A:$I,9,0) -> #N/A | U26: =T26*K26 -> #N/A
A27: 93055409 | B27: NK 40-220/179 | C27: 0.75 | D27: 4 | L27: 4122.63 | M27: =L27/2 -> 2061.315 | R27: =VLOOKUP(E27,'Inertia Bases 2025'!$A:$H,8,0) -> #N/A | T27: =VLOOKUP(G27,'Seismic Springs 2025'!$A:$I,9,0) -> #N/A | U27: =T27*K27 -> #N/A
A28: 93055411 | B28: NK 40-220/167 | C28: 0.55 | D28: 4 | L28: 4038.53 | M28: =L28/2 -> 2019.265 | R28: =VLOOKUP(E28,'Inertia Bases 2025'!$A:$H,8,0) -> #N/A | T28: =VLOOKUP(G28,'Seismic Springs 2025'!$A:$I,9,0) -> #N/A | U28: =T28*K28 -> #N/A
A29: 93055413 | B29: NK 40-225/246 | C29: 22 | D29: 2 | L29: 7784.02 | M29: =L29/2 -> 3892.01 | R29: =VLOOKUP(E29,'Inertia Bases 2025'!$A:$H,8,0) -> #N/A | T29: =VLOOKUP(G29,'Seismic Springs 2025'!$A:$I,9,0) -> #N/A | U29: =T29*K29 -> #N/A
A30: 93055414 | B30: NK 40-225/230 | C30: 18.5 | D30: 2 | L30: 7296.13 | M30: =L30/2 -> 3648.065 | R30: =VLOOKUP(E30,'Inertia Bases 2025'!$A:$H,8,0) -> #N/A | T30: =VLOOKUP(G30,'Seismic Springs 2025'!$A:$I,9,0) -> #N/A | U30: =T30*K30 -> #N/A
A31: 93055415 | B31: NK 40-225/210 | C31: 15 | D31: 2 | L31: 6902.16 | M31: =L31/2 -> 3451.08 | R31: =VLOOKUP(E31,'Inertia Bases 2025'!$A:$H,8,0) -> #N/A | T31: =VLOOKUP(G31,'Seismic Springs 2025'!$A:$I,9,0) -> #N/A | U31: =T31*K31 -> #N/A
A32: 93055417 | B32: NK 40-225/192 | C32: 11 | D32: 2 | E32: 91338087 | F32: 1320 x 740 x 125 | G32: 91338157 | H32: CSM-17 | K32: 4 | L32: 6644.33 | M32: =L32/2 -> 3322.165 | R32: =VLOOKUP(E32,'Inertia Bases 2025'!$A:$H,8,0) -> 541.04 | T32: =VLOOKUP(G32,'Seismic Springs 2025'!$A:$I,9,0) -> 66.3 | U32: =T32*K32 -> 265.2
A33: 93055418 | B33: NK 40-225/173 | C33: 7.5 | D33: 2 | L33: 5605.58 | M33: =L33/2 -> 2802.79 | R33: =VLOOKUP(E33,'Inertia Bases 2025'!$A:$H,8,0) -> #N/A | T33: =VLOOKUP(G33,'Seismic Springs 2025'!$A:$I,9,0) -> #N/A | U33: =T33*K33 -> #N/A
A34: 93055419 | B34: NK 40-225/158 | C34: 5.5 | D34: 2 | L34: 5360.62 | M34: =L34/2 -> 2680.31 | R34: =VLOOKUP(E34,'Inertia Bases 2025'!$A:$H,8,0) -> #N/A | T34: =VLOOKUP(G34,'Seismic Springs 2025'!$A:$I,9,0) -> #N/A | U34: =T34*K34 -> #N/A
A35: 93055420 | B35: NK 40-225/250 | C35: 3 | D35: 4 | E35: 92513065 | F35: 1100 x 800 x 150 | G35: 91338157 | H35: CSM-17 | L35: 4871.85 | M35: =L35/2 -> 2435.925 | R35: =VLOOKUP(E35,'Inertia Bases 2025'!$A:$H,8,0) -> 610.6 | T35: =VLOOKUP(G35,'Seismic Springs 2025'!$A:$I,9,0) -> 66.3 | U35: =T35*K35 -> 0
A36: 93055421 | B36: NK 40-225/226 | C36: 2.2 | D36: 4 | L36: 4755.35 | M36: =L36/2 -> 2377.675 | R36: =VLOOKUP(E36,'Inertia Bases 2025'!$A:$H,8,0) -> #N/A | T36: =VLOOKUP(G36,'Seismic Springs 2025'!$A:$I,9,0) -> #N/A | U36: =T36*K36 -> #N/A
A37: 93055422 | B37: NK 40-225/199 | C37: 1.5 | D37: 4 | L37: 4520.65 | M37: =L37/2 -> 2260.325 | R37: =VLOOKUP(E37,'Inertia Bases 2025'!$A:$H,8,0) -> #N/A | T37: =VLOOKUP(G37,'Seismic Springs 2025'!$A:$I,9,0) -> #N/A | U37: =T37*K37 -> #N/A
A38: 93055423 | B38: NK 40-225/182 | C38: 1.1 | D38: 4 | L38: 4443.12 | M38: =L38/2 -> 2221.56 | R38: =VLOOKUP(E38,'Inertia Bases 2025'!$A:$H,8,0) -> #N/A | T38: =VLOOKUP(G38,'Seismic Springs 2025'!$A:$I,9,0) -> #N/A | U38: =T38*K38 -> #N/A
A39: 93055424 | B39: NK 40-225/162 | C39: 0.75 | D39: 4 | L39: 4148.24 | M39: =L39/2 -> 2074.12 | R39: =VLOOKUP(E39,'Inertia Bases 2025'!$A:$H,8,0) -> #N/A | T39: =VLOOKUP(G39,'Seismic Springs 2025'!$A:$I,9,0) -> #N/A | U39: =T39*K39 -> #N/A
A40: 93055426 | B40: NK 50-225/240 | C40: 30 | D40: 2 | L40: 9278.9 | M40: =L40/2 -> 4639.45 | R40: =VLOOKUP(E40,'Inertia Bases 2025'!$A:$H,8,0) -> #N/A | T40: =VLOOKUP(G40,'Seismic Springs 2025'!$A:$I,9,0) -> #N/A | U40: =T40*K40 -> #N/A
...

Sheet CR BOM
A1: Item No | B1: Name | C1: Pump List | D1: Pump Nett | E1: IP-56 Nett | F1: IP-66 Nett | G1: Base Nett | H1: Inertia SKU | I1: Inertia Size | J1: Inertia Nett | K1: RM Nett | L1: Mount Qty | M1: RM Total | N1: Seismic SKU | O1: Seismic Name | P1: Seismic Qty | Q1: Seismic Total
A2: 92900978 | B2: CR1-10 | C2: 1811 | D2: 905.5 | G2: 520 | K2: 11.83 | L2: 4 | M2: =K2*L2 -> 47.32
A3: 92901041 | B3: CR1-10 | C3: 1902 | D3: 951 | G3: 520 | K3: 11.83 | L3: 4 | M3: =K3*L3 -> 47.32
A4: 96516180 | B4: CR1-10 | C4: 1694 | D4: 847 | G4: 520 | K4: 11.83 | L4: 4 | M4: =K4*L4 -> 47.32
A5: 96516246 | B5: CR1-10 | C5: 1784 | D5: 892 | G5: 520 | K5: 11.83 | L5: 4 | M5: =K5*L5 -> 47.32
A6: 92900981 | B6: CR1-11 | C6: 1888 | D6: 944 | G6: 520 | K6: 11.83 | L6: 4 | M6: =K6*L6 -> 47.32
A7: 92901044 | B7: CR1-11 | C7: 1979 | D7: 989.5 | G7: 520 | K7: 11.83 | L7: 4 | M7: =K7*L7 -> 47.32
A8: 96516181 | B8: CR1-11 | C8: 1771 | D8: 885.5 | G8: 520 | K8: 11.83 | L8: 4 | M8: =K8*L8 -> 47.32
A9: 96516247 | B9: CR1-11 | C9: 1861 | D9: 930.5 | G9: 520 | K9: 11.83 | L9: 4 | M9: =K9*L9 -> 47.32
A10: 92900982 | B10: CR1-12 | C10: 2060 | D10: 1030 | G10: 520 | K10: 11.83 | L10: 4 | M10: =K10*L10 -> 47.32
A11: 92901045 | B11: CR1-12 | C11: 2150 | D11: 1075 | G11: 520 | K11: 11.83 | L11: 4 | M11: =K11*L11 -> 47.32
A12: 96516183 | B12: CR1-12 | C12: 1849 | D12: 924.5 | G12: 520 | K12: 11.83 | L12: 4 | M12: =K12*L12 -> 47.32
A13: 96516248 | B13: CR1-12 | C13: 1939 | D13: 969.5 | G13: 520 | K13: 11.83 | L13: 4 | M13: =K13*L13 -> 47.32
... A95: 92959626 | B95: CR10-5 | C95: 3538 | D95: 1769 | G95: 520 | K95: 11.83 | L95: 4 | M95: =K95*L95 -> 47.32
A96: 96500967 | B96: CR10-5 | C96: 3045 | D96: 1522.5 | F96: 135 | G96: 520 | K96: 11.83 | L96: 4 | M96: =K96*L96 -> 47.32
A97: 92959628 | B97: CR10-6 | C97: 3373 | D97: 1686.5 | G97: 520 | K97: 11.83 | L97: 4 | M97: =K97*L97 -> 47.32
A98: 96500968 | B98: CR10-6 | C98: 3209 | D98: 1604.5 | G98: 520 | K98: 11.83 | L98: 4 | M98: =K98*L98 -> 47.32
A99: 96500969 | B99: CR10-7 | C99: 3535 | D99: 1767.5 | G99: 520 | K99: 11.83 | L99: 4 | M99: =K99*L99 -> 47.32
A100: 96500970 | B100: CR10-8 | C100: 3699 | D100: 1849.5 | G100: 520 | K100: 11.83 | L100: 4 | M100: =K100*L100 -> 47.32
A101: 96500971 | B101: CR10-9 | C101: 3870 | D101: 1935 | G101: 520 | K101: 11.83 | L101: 4 | M101: =K101*L101 -> 47.32
A102: 99142431 | B102: CR125-1 | C102: 11052 | D102: 5526 | M102: =K102*L102 -> 0
A103: 99142574 | B103: CR125-2 | C103: 18036 | D103: 9018 | M103: =K103*L103 -> 0
A104: 99142573 | B104: CR125-2-1 | C104: 16127 | D104: 8063.5 | M104: =K104*L104 -> 0
A105: 99142432 | B105: CR125-2-2 | C105: 13765 | D105: 6882.5 | M105: =K105*L105 -> 0
A106: 99751480 | B106: CR125-3 | C106: 19973 | D106: 9986.5 | M106: =K106*L106 -> 0
A107: 99751479 | B107: CR125-3-1 | C107: 19342 | D107: 9671 | M107: =K107*L107 -> 0
A108: 99751483 | B108: CR125-4 | C108: 26409 | D108: 13204.5 | M108: =K108*L108 -> 0
A109: 99751482 | B109: CR125-4-2 | C109: 20861 | D109: 10430.5 | M109: =K109*L109 -> 0
A110: 99751486 | B110: CR125-5 | C110: 32401 | D110: 16200.5 | M110: =K110*L110 -> 0
A111: 92959640 | B111: CR15-1 | C111: 2959 | D111: 1479.5 | G111: 520 | K111: 11.83 | L111: 4 | M111: =K111*L111 -> 47.32
A112: 96501697 | B112: CR15-1 | C112: 2622 | D112: 1311 | G112: 520 | K112: 11.83 | L112: 4 | M112: =K112*L112 -> 47.32
A113: 96501901 | B113: CR15-10 | C113: 8141 | D113: 4070.5 | G113: 520 | K113: 11.83 | L113: 4 | M113: =K113*L113 -> 47.32
A114: 96501902 | B114: CR15-12 | C114: 8579 | D114: 4289.5 | G114: 520 | K114: 11.83 | L114: 4 | M114: =K114*L114 -> 47.32
A115: 96501903 | B115: CR15-14 | C115: 9025 | D115: 4512.5 | G115: 520 | K115: 11.83 | L115: 4 | M115: =K115*L115 -> 47.32
A116: 96501904 | B116: CR15-17 | C116: 11540 | D116: 5770 | G116: 520 | K116: 11.83 | L116: 4 | M116: =K116*L116 -> 47.32
A117: 92959642 | B117: CR15-2 | C117: 3795 | D117: 1897.5 | G117: 520 | K117: 11.83 | L117: 4 | M117: =K117*L117 -> 47.32
A118: 96501698 | B118: CR15-2 | C118: 3305 | D118: 1652.5 | G118: 520 | K118: 11.83 | L118: 4 | M118: =K118*L118 -> 47.32
A119: 96501699 | B119: CR15-3 | C119: 3820 | D119: 1910 | F119: 62 | G119: 520 | K119: 11.83 | L119: 4 | M119: =K119*L119 -> 47.32
A120: 96501895 | B120: CR15-4 | C120: 4437 | D120: 2218.5 | G120: 520 | K120: 11.83 | L120: 4 | M120: =K120*L120 -> 47.32
A121: 96501896 | B121: CR15-5 | C121: 4657 | D121: 2328.5 | G121: 520 | K121: 11.83 | L121: 4 | M121: =K121*L121 -> 47.32
...

Sheet CRE BOM
A1: Item No | B1: Name | C1: Pump List | D1: Pump Nett | E1: IP-56 Nett | F1: IP-66 Nett | G1: Base Nett | H1: Inertia SKU | I1: Inertia Size | J1: Inertia Nett | K1: RM Nett | L1: Mount Qty | M1: RM Total | N1: Seismic SKU | O1: Seismic Name | P1: Seismic Qty | Q1: Seismic Total
A2: 92959143 | B2: CRE95-1 | C2: 20908 | D2: 10454
A3: 92959148 | B3: CRE95-2-2 | C3: 24730 | D3: 12365
A4: 92959162 | B4: CRE95-2-1 | C4: 27759 | D4: 13879.5
A5: 92959181 | B5: CRE125-1-1 | C5: 19410 | D5: 9705
A6: 92959185 | B6: CRE125-1 | C6: 24927 | D6: 12463.5
A7: 92959225 | B7: CRE155-1-1 | C7: 23923 | D7: 11961.5
A8: 92962276 | B8: CRE32-4 | C8: 20744 | D8: 10372
A9: 92962277 | B9: CRE32-5-2 | C9: 21331 | D9: 10665.5
A10: 92962278 | B10: CRE32-5 | C10: 23215 | D10: 11607.5
A11: 92962279 | B11: CRE32-6 | C11: 23802 | D11: 11901
A12: 92962280 | B12: CRE32-6 | C12: 25155 | D12: 12577.5
A13: 92962281 | B13: CRE32-7 | C13: 27757 | D13: 13878.5
... A149: 99707619 | B149: CRE95-1-1 | C149: 16712 | D149: 8356

Sheet CRI BOM
A1: Item No | B1: Name | C1: Pump List | D1: Pump Nett | E1: IP-56 Nett | F1: IP-66 Nett | G1: Base Nett | H1: Inertia SKU | I1: Inertia Size | J1: Inertia Nett | K1: RM Nett | L1: Mount Qty | M1: RM Total | N1: Seismic SKU | O1: Seismic Name | P1: Seismic Qty | Q1: Seismic Total
A2: 92899847 | B2: CRI1S-2 | C2: 1526 | D2: 763 | G2: 520 | K2: 11.83 | L2: 4 | M2: =K2*L2 -> 47.32
A3: 92899848 | B3: CRI1S-3 | C3: 1574 | D3: 787 | G3: 520 | K3: 11.83 | L3: 4 | M3: =K3*L3 -> 47.32
A4: 92899849 | B4: CRI1S-4 | C4: 1621 | D4: 810.5 | G4: 520 | K4: 11.83 | L4: 4 | M4: =K4*L4 -> 47.32
A5: 92899850 | B5: CRI1S-5 | C5: 1668 | D5: 834 | G5: 520 | K5: 11.83 | L5: 4 | M5: =K5*L5 -> 47.32
A6: 92899851 | B6: CRI1S-6 | C6: 1716 | D6: 858 | G6: 520 | K6: 11.83 | L6: 4 | M6: =K6*L6 -> 47.32
A7: 92899852 | B7: CRI1S-7 | C7: 1763 | D7: 881.5 | G7: 520 | K7: 11.83 | L7: 4 | M7: =K7*L7 -> 47.32
A8: 92899853 | B8: CRI1S-8 | C8: 1812 | D8: 906 | G8: 520 | K8: 11.83 | L8: 4 | M8: =K8*L8 -> 47.32
A9: 92899854 | B9: CRI1S-9 | C9: 1859 | D9: 929.5 | G9: 520 | K9: 11.83 | L9: 4 | M9: =K9*L9 -> 47.32
A10: 92899855 | B10: CRI1S-10 | C10: 1904 | D10: 952 | G10: 520 | K10: 11.83 | L10: 4 | M10: =K10*L10 -> 47.32
A11: 92899856 | B11: CRI1S-11 | C11: 1952 | D11: 976 | G11: 520 | K11: 11.83 | L11: 4 | M11: =K11*L11 -> 47.32
A12: 92899857 | B12: CRI1S-12 | C12: 1999 | D12: 999.5 | G12: 520 | K12: 11.83 | L12: 4 | M12: =K12*L12 -> 47.32
A13: 92899858 | B13: CRI1S-13 | C13: 2047 | D13: 1023.5 | G13: 520 | K13: 11.83 | L13: 4 | M13: =K13*L13 -> 47.32
... A159: 92902523 | B159: CRI5-16 | C159: 3706 | D159: 1853 | G159: 520 | K159: 11.83 | L159: 4 | M159: =K159*L159 -> 47.32
A160: 92982745 | B160: CRI20-2 | C160: 4049 | D160: 2024.5
A161: 92982747 | B161: CRI10-6 | C161: 3988 | D161: 1994 | G161: 520 | K161: 11.83 | L161: 4 | M161: =K161*L161 -> 47.32
A162: 92982748 | B162: CRI10-5 | C162: 3819 | D162: 1909.5 | G162: 520 | K162: 11.83 | L162: 4 | M162: =K162*L162 -> 47.32
A163: 92982760 | B163: CRI15-2 | C163: 4133 | D163: 2066.5 | G163: 520 | K163: 11.83 | L163: 4 | M163: =K163*L163 -> 47.32
A164: 92983552 | B164: CRI10-1 | C164: 2435 | D164: 1217.5 | G164: 520 | K164: 11.83 | L164: 4 | M164: =K164*L164 -> 47.32
A165: 92983556 | B165: CRI10-2 | C165: 2639 | D165: 1319.5 | G165: 520 | K165: 11.83 | L165: 4 | M165: =K165*L165 -> 47.32
A166: 92983561 | B166: CRI10-3 | C166: 3121 | D166: 1560.5 | G166: 520 | K166: 11.83 | L166: 4 | M166: =K166*L166 -> 47.32
A167: 92983566 | B167: CRI10-4 | C167: 3535 | D167: 1767.5 | G167: 520 | K167: 11.83 | L167: 4 | M167: =K167*L167 -> 47.32
A168: 92983568 | B168: CRI15-1 | C168: 3335 | D168: 1667.5 | G168: 520 | K168: 11.83 | L168: 4 | M168: =K168*L168 -> 47.32
A169: 92983569 | B169: CRI20-1 | C169: 3255 | D169: 1627.5
A170: 96500345 | B170: CRI20-1 | C170: 2943 | D170: 1471.5
A171: 96500346 | B171: CRI20-2 | C171: 3595 | D171: 1797.5
A172: 96500526 | B172: CRI20-3 | C172: 4830 | D172: 2415
A173: 96500527 | B173: CRI20-4 | C173: 5863 | D173: 2931.5
A174: 96500528 | B174: CRI20-5 | C174: 6088 | D174: 3044
A175: 96500529 | B175: CRI20-6 | C175: 7026 | D175: 3513
A176: 96500530 | B176: CRI20-7 | C176: 7255 | D176: 3627.5
A177: 96500531 | B177: CRI20-8 | C177: 9001 | D177: 4500.5
A178: 96500532 | B178: CRI20-10 | C178: 9456 | D178: 4728
A179: 96500533 | B179: CRI20-12 | C179: 11495 | D179: 5747.5
A180: 96500534 | B180: CRI20-14 | C180: 12045 | D180: 6022.5
A181: 96500535 | B181: CRI20-17 | C181: 14213 | D181: 7106.5
A182: 96500992 | B182: CRI10-1 | C182: 2327 | D182: 1163.5 | G182: 520 | K182: 11.83 | L182: 4 | M182: =K182*L182 -> 47.32
A183: 96500993 | B183: CRI10-2 | C183: 2411 | D183: 1205.5 | G183: 520 | K183: 11.83 | L183: 4 | M183: =K183*L183 -> 47.32
A184: 96500994 | B184: CRI10-3 | C184: 2762 | D184: 1381 | G184: 520 | K184: 11.83 | L184: 4 | M184: =K184*L184 -> 47.32
A185: 96500995 | B185: CRI10-4 | C185: 3063 | D185: 1531.5 | G185: 520 | K185: 11.83 | L185: 4 | M185: =K185*L185 -> 47.32
...

Sheet CRIE BOM
A1: Item No | B1: Name | C1: Pump List | D1: Pump Nett | E1: IP-56 Nett | F1: IP-66 Nett | G1: Base Nett | H1: Inertia SKU | I1: Inertia Size | J1: Inertia Nett | K1: RM Nett | L1: Mount Qty | M1: RM Total | N1: Seismic SKU | O1: Seismic Name | P1: Seismic Qty | Q1: Seismic Total
A2: 93150535 | B2: CRIE1-3 | C2: 3015 | D2: 1507.5
A3: 93150536 | B3: CRIE1-4 | C3: 3086 | D3: 1543
A4: 93150537 | B4: CRIE1-5 | C4: 3241 | D4: 1620.5
A5: 93150538 | B5: CRIE1-6 | C5: 3307 | D5: 1653.5
A6: 93150539 | B6: CRIE1-6 | C6: 3377 | D6: 1688.5
A7: 93150550 | B7: CRIE1-9 | C7: 3607 | D7: 1803.5
A8: 93150552 | B8: CRIE1-12 | C8: 4462 | D8: 2231
A9: 93150553 | B9: CRIE1-13 | C9: 4171 | D9: 2085.5
A10: 93150554 | B10: CRIE1-17 | C10: 5070 | D10: 2535
A11: 93150555 | B11: CRIE3-2 | C11: 2989 | D11: 1494.5
A12: 93150556 | B12: CRIE3-3 | C12: 3111 | D12: 1555.5
A13: 93150558 | B13: CRIE3-4 | C13: 3247 | D13: 1623.5
... A104: 99852769 | B104: CRIE64-1 | C104: 18867 | D104: 9433.5

Sheet CRN BOM
A1: Item No | B1: Name | C1: Pump List | D1: Pump Nett | E1: IP-56 Nett | F1: IP-66 Nett | G1: Base Nett | H1: Inertia SKU | I1: Inertia Size | J1: Inertia Nett | K1: RM Nett | L1: Mount Qty | M1: RM Total | N1: Seismic SKU | O1: Seismic Name | P1: Seismic Qty | Q1: Seismic Total
A2: 92501229 | B2: CRN185-2-2 | C2: 50110 | D2: 25055
A3: 92501241 | B3: CRN185-2 | C3: 62221 | D3: 31110.5
A4: 92501258 | B4: CRN185-3-3 | C4: 72528 | D4: 36264
A5: 92501275 | B5: CRN185-3 | C5: 86857 | D5: 43428.5
A6: 92501288 | B6: CRN185-4-3 | C6: 88878 | D6: 44439
A7: 92501326 | B7: CRN185-4 | C7: 103435 | D7: 51717.5
A8: 92501790 | B8: CRN185-5-3 | C8: 111594 | D8: 55797
A9: 92501806 | B9: CRN185-5 | C9: 111594 | D9: 55797
A10: 92501843 | B10: CRN185-6-3 | C10: 126584 | D10: 63292
A11: 92501857 | B11: CRN185-6 | C11: 126584 | D11: 63292
A12: 92501881 | B12: CRN185-7-3 | C12: 146854 | D12: 73427
A13: 92501906 | B13: CRN185-7 | C13: 146854 | D13: 73427
... A554: 99751655 | B554: CRN155-8-2 | C554: 87969 | D554: 43984.5

Sheet CRNE BOM
A1: Item No | B1: Name | C1: Pump List | D1: Pump Nett | E1: IP-56 Nett | F1: IP-66 Nett | G1: Base Nett | H1: Inertia SKU | I1: Inertia Size | J1: Inertia Nett | K1: RM Nett | L1: Mount Qty | M1: RM Total | N1: Seismic SKU | O1: Seismic Name | P1: Seismic Qty | Q1: Seismic Total
A2: 92959167 | B2: CRNE95-1 | C2: 31419 | D2: 15709.5
A3: 92959172 | B3: CRNE95-2-2 | C3: 36195 | D3: 18097.5
A4: 92959178 | B4: CRNE95-2-1 | C4: 40640 | D4: 20320
A5: 92959207 | B5: CRNE125-1-1 | C5: 29447 | D5: 14723.5
A6: 92959217 | B6: CRNE125-1 | C6: 36927 | D6: 18463.5
A7: 92959229 | B7: CRNE155-1-1 | C7: 36450 | D7: 18225
A8: 92962319 | B8: CRNE32-4 | C8: 29534 | D8: 14767
A9: 92962320 | B9: CRNE32-5-2 | C9: 30322 | D9: 15161
A10: 92962321 | B10: CRNE32-5 | C10: 33251 | D10: 16625.5
A11: 92962322 | B11: CRNE32-6 | C11: 34039 | D11: 17019.5
A12: 92962323 | B12: CRNE32-6 | C12: 35685 | D12: 17842.5
A13: 92962324 | B13: CRNE32-7 | C13: 38856 | D13: 19428
... A117: 99315835 | B117: CRNE32-2-1 | C117: 15166 | D117: 7583
A118: 99655972 | B118: CRNE95-1-1 | C118: 24731 | D118: 12365.5 | H118: 99102010 | I118: 620 x 620 x 310 | J118: 646.67 | N118: 92932673 | O118: CSM-16 | P118: 4 | Q118: 238.08

Sheet TP BOM
A1: Item No | B1: Name | C1: Base | D1: RM SKU | E1: RM Name | F1: Pump List | G1: Pump Nett | H1: IP-56 Nett | I1: IP-66 Nett | J1: Base Nett | K1: Inertia SKU | L1: Inertia Size | M1: Rubber Mount Nett | N1: Seismic Spring SKU | O1: Seismic Spring Name | P1: Mount Qty | Q1: RM Total Nett | R1: Seismic Spring Nett | S1: Seis Total Nett | T1: Inertia Nett
A2: 96086842 | B2: TP 40-240/2 A-F-B-BQQE-IX1 | F2: 4703 | G2: =CEILING(F2*0.55,1) -> 2587 | R2: =VLOOKUP(N2,'Seismic Springs 2025'!$A:$I,9,0) -> #N/A | S2: =P2*R2 -> #N/A | T2: =VLOOKUP(K2,'Inertia Bases 2025'!$A:$H,8,0) -> #N/A
A3: 96086843 | B3: TP 40-300/2 A-F-B-BQQE-JX1 | F3: 4942 | G3: =CEILING(F3*0.55,1) -> 2719 | R3: =VLOOKUP(N3,'Seismic Springs 2025'!$A:$I,9,0) -> #N/A | S3: =P3*R3 -> #N/A | T3: =VLOOKUP(K3,'Inertia Bases 2025'!$A:$H,8,0) -> #N/A
A4: 96087029 | B4: TP 50-190/2 A-F-B-BQQE-HX1 | D4: 92996501 | E4: NR1 - Yellow | F4: 4328 | G4: =CEILING(F4*0.55,1) -> 2381 | I4: =CEILING(2505.68-G4,1) -> 125 | J4: 530 | M4: 11.7 | P4: 4 | Q4: =M4*P4 -> 46.8 | R4: =VLOOKUP(N4,'Seismic Springs 2025'!$A:$I,9,0) -> #N/A | S4: =P4*R4 -> #N/A | T4: =VLOOKUP(K4,'Inertia Bases 2025'!$A:$H,8,0) -> #N/A
A5: 96087030 | B5: TP 50-240/2 A-F-B-BQQE-IX1 | F5: 4503 | G5: =CEILING(F5*0.55,1) -> 2477 | R5: =VLOOKUP(N5,'Seismic Springs 2025'!$A:$I,9,0) -> #N/A | S5: =P5*R5 -> #N/A | T5: =VLOOKUP(K5,'Inertia Bases 2025'!$A:$H,8,0) -> #N/A
A6: 96087031 | B6: TP 50-290/2 A-F-B-BQQE-JX1 | F6: 4766 | G6: =CEILING(F6*0.55,1) -> 2622 | R6: =VLOOKUP(N6,'Seismic Springs 2025'!$A:$I,9,0) -> #N/A | S6: =P6*R6 -> #N/A | T6: =VLOOKUP(K6,'Inertia Bases 2025'!$A:$H,8,0) -> #N/A
A7: 96087139 | B7: TP 50-190/4 A-F-B-BQQE-IX3 | F7: 6238 | G7: =CEILING(F7*0.55,1) -> 3431 | R7: =VLOOKUP(N7,'Seismic Springs 2025'!$A:$I,9,0) -> #N/A | S7: =P7*R7 -> #N/A | T7: =VLOOKUP(K7,'Inertia Bases 2025'!$A:$H,8,0) -> #N/A
A8: 96087140 | B8: TP 50-230/4 A-F-B-BQQE-JX3 | F8: 6644 | G8: =CEILING(F8*0.55,1) -> 3655 | R8: =VLOOKUP(N8,'Seismic Springs 2025'!$A:$I,9,0) -> #N/A | S8: =P8*R8 -> #N/A | T8: =VLOOKUP(K8,'Inertia Bases 2025'!$A:$H,8,0) -> #N/A
A9: 96087224 | B9: TP 50-360/2 A-F-B-BQQE-KX1 | F9: 5619 | G9: =CEILING(F9*0.55,1) -> 3091 | R9: =VLOOKUP(N9,'Seismic Springs 2025'!$A:$I,9,0) -> #N/A | S9: =P9*R9 -> #N/A | T9: =VLOOKUP(K9,'Inertia Bases 2025'!$A:$H,8,0) -> #N/A
A10: 96087225 | B10: TP 50-430/2 A-F-B-BQQE-LX1 | F10: 7205 | G10: =CEILING(F10*0.55,1) -> 3963 | R10: =VLOOKUP(N10,'Seismic Springs 2025'!$A:$I,9,0) -> #N/A | S10: =P10*R10 -> #N/A | T10: =VLOOKUP(K10,'Inertia Bases 2025'!$A:$H,8,0) -> #N/A
A11: 96087462 | B11: TP 65-150/4 A-F-B-BQQE-IX3 | F11: 6183 | G11: =CEILING(F11*0.55,1) -> 3401 | R11: =VLOOKUP(N11,'Seismic Springs 2025'!$A:$I,9,0) -> #N/A | S11: =P11*R11 -> #N/A | T11: =VLOOKUP(K11,'Inertia Bases 2025'!$A:$H,8,0) -> #N/A
A12: 96087463 | B12: TP 65-170/4 A-F-B-BQQE-JX3 | F12: 6398 | G12: =CEILING(F12*0.55,1) -> 3519 | R12: =VLOOKUP(N12,'Seismic Springs 2025'!$A:$I,9,0) -> #N/A | S12: =P12*R12 -> #N/A | T12: =VLOOKUP(K12,'Inertia Bases 2025'!$A:$H,8,0) -> #N/A
A13: 96087554 | B13: TP 65-340/2 A-F-B-BQQE-LX1 | F13: 7362 | G13: =CEILING(F13*0.55,1) -> 4050 | R13: =VLOOKUP(N13,'Seismic Springs 2025'!$A:$I,9,0) -> #N/A | S13: =P13*R13 -> #N/A | T13: =VLOOKUP(K13,'Inertia Bases 2025'!$A:$H,8,0) -> #N/A
A14: 96087555 | B14: TP 65-410/2 A-F-B-BQQE-MX1 | F14: 7682 | G14: =CEILING(F14*0.55,1) -> 4226 | R14: =VLOOKUP(N14,'Seismic Springs 2025'!$A:$I,9,0) -> #N/A | S14: =P14*R14 -> #N/A | T14: =VLOOKUP(K14,'Inertia Bases 2025'!$A:$H,8,0) -> #N/A
A15: 96087556 | B15: TP 65-460/2 A-F-B-BQQE-NX1 | F15: 11091 | G15: =CEILING(F15*0.55,1) -> 6101 | R15: =VLOOKUP(N15,'Seismic Springs 2025'!$A:$I,9,0) -> #N/A | S15: =P15*R15 -> #N/A | T15: =VLOOKUP(K15,'Inertia Bases 2025'!$A:$H,8,0) -> #N/A
A16: 96087557 | B16: TP 65-550/2 A-F-B-BQQE-OX1 | F16: 12763 | G16: =CEILING(F16*0.55,1) -> 7020 | R16: =VLOOKUP(N16,'Seismic Springs 2025'!$A:$I,9,0) -> #N/A | S16: =P16*R16 -> #N/A | T16: =VLOOKUP(K16,'Inertia Bases 2025'!$A:$H,8,0) -> #N/A
... A46: 96109344 | B46: TP 100-250/4 A-F-B-BQQE-NX3 | F46: 14054 | G46: =CEILING(F46*0.55,1) -> 7730 | R46: =VLOOKUP(N46,'Seismic Springs 2025'!$A:$I,9,0) -> #N/A | S46: =P46*R46 -> #N/A | T46: =VLOOKUP(K46,'Inertia Bases 2025'!$A:$H,8,0) -> #N/A
A47: 96109345 | B47: TP 100-330/4 A-F-B-BQQE-OX3 | F47: 16835 | G47: =CEILING(F47*0.55,1) -> 9260 | K47: 92513065 | L47: 1100 x 800 x 150 | N47: 91338157 | O47: CSM-17 | P47: 4 | R47: =VLOOKUP(N47,'Seismic Springs 2025'!$A:$I,9,0) -> 66.3 | S47: =P47*R47 -> 265.2 | T47: =VLOOKUP(K47,'Inertia Bases 2025'!$A:$H,8,0) -> 610.6
A48: 96109346 | B48: TP 100-370/4 A-F-B-BQQE-PX3 | F48: 19126 | G48: =CEILING(F48*0.55,1) -> 10520 | R48: =VLOOKUP(N48,'Seismic Springs 2025'!$A:$I,9,0) -> #N/A | S48: =P48*R48 -> #N/A | T48: =VLOOKUP(K48,'Inertia Bases 2025'!$A:$H,8,0) -> #N/A
A49: 97851334 | B49: TP 40-120/2 A-F-A-BQQE-DX1 | F49: 2365 | G49: =CEILING(F49*0.55,1) -> 1301 | R49: =VLOOKUP(N49,'Seismic Springs 2025'!$A:$I,9,0) -> #N/A | S49: =P49*R49 -> #N/A | T49: =VLOOKUP(K49,'Inertia Bases 2025'!$A:$H,8,0) -> #N/A
A50: 98066916 | B50: TP 40-230/2 A-F-A-BQQE-GX1 | F50: 2985 | G50: =CEILING(F50*0.55,1) -> 1642 | R50: =VLOOKUP(N50,'Seismic Springs 2025'!$A:$I,9,0) -> #N/A | S50: =P50*R50 -> #N/A | T50: =VLOOKUP(K50,'Inertia Bases 2025'!$A:$H,8,0) -> #N/A
A51: 98122409 | B51: TP 40-60/2 A-F-A-BQQE-CX1 | F51: 1881 | G51: =CEILING(F51*0.55,1) -> 1035 | R51: =VLOOKUP(N51,'Seismic Springs 2025'!$A:$I,9,0) -> #N/A | S51: =P51*R51 -> #N/A | T51: =VLOOKUP(K51,'Inertia Bases 2025'!$A:$H,8,0) -> #N/A
A52: 98133648 | B52: TP 50-180/2 A-F-A-BQQE-FX1 | F52: 3279 | G52: =CEILING(F52*0.55,1) -> 1804 | R52: =VLOOKUP(N52,'Seismic Springs 2025'!$A:$I,9,0) -> #N/A | S52: =P52*R52 -> #N/A | T52: =VLOOKUP(K52,'Inertia Bases 2025'!$A:$H,8,0) -> #N/A
A53: 98133671 | B53: TP 40-180/2 A-F-A-BQQE-EX1 | F53: 2801 | G53: =CEILING(F53*0.55,1) -> 1541 | R53: =VLOOKUP(N53,'Seismic Springs 2025'!$A:$I,9,0) -> #N/A | S53: =P53*R53 -> #N/A | T53: =VLOOKUP(K53,'Inertia Bases 2025'!$A:$H,8,0) -> #N/A
A54: 98182027 | B54: TP 50-60/2 A-F-A-BQQE-DX1 | F54: 2366 | G54: =CEILING(F54*0.55,1) -> 1302 | R54: =VLOOKUP(N54,'Seismic Springs 2025'!$A:$I,9,0) -> #N/A | S54: =P54*R54 -> #N/A | T54: =VLOOKUP(K54,'Inertia Bases 2025'!$A:$H,8,0) -> #N/A
A55: 98279255 | B55: TP 50-120/2 A-F-A-BQQE-FX1 | F55: 2903 | G55: =CEILING(F55*0.55,1) -> 1597 | R55: =VLOOKUP(N55,'Seismic Springs 2025'!$A:$I,9,0) -> #N/A | S55: =P55*R55 -> #N/A | T55: =VLOOKUP(K55,'Inertia Bases 2025'!$A:$H,8,0) -> #N/A
A56: 98294231 | B56: TP 40-190/2 A-F-A-BQQE-FX1 | F56: 2893 | G56: =CEILING(F56*0.55,1) -> 1592 | R56: =VLOOKUP(N56,'Seismic Springs 2025'!$A:$I,9,0) -> #N/A | S56: =P56*R56 -> #N/A | T56: =VLOOKUP(K56,'Inertia Bases 2025'!$A:$H,8,0) -> #N/A
A57: 98299122 | B57: TP 32-90/2 A-O-A-BQQE-DX1 | F57: 1978 | G57: =CEILING(F57*0.55,1) -> 1088 | R57: =VLOOKUP(N57,'Seismic Springs 2025'!$A:$I,9,0) -> #N/A | S57: =P57*R57 -> #N/A | T57: =VLOOKUP(K57,'Inertia Bases 2025'!$A:$H,8,0) -> #N/A
A58: 98346582 | B58: TP 32-90/2 A-O-A-BQQE-DX1 | F58: 1646 | G58: =CEILING(F58*0.55,1) -> 906 | R58: =VLOOKUP(N58,'Seismic Springs 2025'!$A:$I,9,0) -> #N/A | S58: =P58*R58 -> #N/A | T58: =VLOOKUP(K58,'Inertia Bases 2025'!$A:$H,8,0) -> #N/A
A59: 98420371 | B59: TP 65-180/2 A-F-A-BQQE-HX1 | F59: 3986 | G59: =CEILING(F59*0.55,1) -> 2193 | R59: =VLOOKUP(N59,'Seismic Springs 2025'!$A:$I,9,0) -> #N/A | S59: =P59*R59 -> #N/A | T59: =VLOOKUP(K59,'Inertia Bases 2025'!$A:$H,8,0) -> #N/A
... A62: 98742355 | B62: TP 65-250/2 A-F-B-BQQE-KX1 | F62: 5459 | G62: =CEILING(F62*0.55,1) -> 3003 | R62: =VLOOKUP(N62,'Seismic Springs 2025'!$A:$I,9,0) -> #N/A | S62: =P62*R62 -> #N/A | T62: =VLOOKUP(K62,'Inertia Bases 2025'!$A:$H,8,0) -> #N/A
A63: 98742400 | B63: TP 65-210/2 A-F-B-BQQE-JX1 | D63: 92996501 | E63: NR1 - Yellow | F63: 4836 | G63: =CEILING(F63*0.55,1) -> 2660 | I63: =2938.37-G63 -> 278.37 | J63: 520 | M63: 11.7 | P63: 4 | Q63: =M63*P63 -> 46.8 | R63: =VLOOKUP(N63,'Seismic Springs 2025'!$A:$I,9,0) -> #N/A | S63: =P63*R63 -> #N/A | T63: =VLOOKUP(K63,'Inertia Bases 2025'!$A:$H,8,0) -> #N/A
A64: 98742915 | B64: TP 50-140/4 A-F-B-BQQE-HX3 | F64: 5211 | G64: =CEILING(F64*0.55,1) -> 2867 | R64: =VLOOKUP(N64,'Seismic Springs 2025'!$A:$I,9,0) -> #N/A | S64: =P64*R64 -> #N/A | T64: =VLOOKUP(K64,'Inertia Bases 2025'!$A:$H,8,0) -> #N/A
A65: 98743320 | B65: TP 40-140/4 A-F-B-BQQE-GX3 | F65: 4933 | G65: =CEILING(F65*0.55,1) -> 2714 | R65: =VLOOKUP(N65,'Seismic Springs 2025'!$A:$I,9,0) -> #N/A | S65: =P65*R65 -> #N/A | T65: =VLOOKUP(K65,'Inertia Bases 2025'!$A:$H,8,0) -> #N/A
A66: 98743360 | B66: TP 40-110/4 A-F-B-BQQE-FX3 | F66: 4374 | G66: =CEILING(F66*0.55,1) -> 2406 | R66: =VLOOKUP(N66,'Seismic Springs 2025'!$A:$I,9,0) -> #N/A | S66: =P66*R66 -> #N/A | T66: =VLOOKUP(K66,'Inertia Bases 2025'!$A:$H,8,0) -> #N/A
A67: 98810439 | B67: TP 50-120/2 A-F-A-BQQE-FX1 | F67: 3265 | G67: =CEILING(F67*0.55,1) -> 1796 | R67: =VLOOKUP(N67,'Seismic Springs 2025'!$A:$I,9,0) -> #N/A | S67: =P67*R67 -> #N/A | T67: =VLOOKUP(K67,'Inertia Bases 2025'!$A:$H,8,0) -> #N/A
A68: 98843904 | B68: TP 80-120/2 AI-F-A-BQQE-HX1 | F68: 4632 | G68: =CEILING(F68*0.55,1) -> 2548 | R68: =VLOOKUP(N68,'Seismic Springs 2025'!$A:$I,9,0) -> #N/A | S68: =P68*R68 -> #N/A | T68: =VLOOKUP(K68,'Inertia Bases 2025'!$A:$H,8,0) -> #N/A
A69: 98957960 | B69: TP 40-60/2 A-F-A-BQQE-CX1 | F69: 2214 | G69: =CEILING(F69*0.55,1) -> 1218 | R69: =VLOOKUP(N69,'Seismic Springs 2025'!$A:$I,9,0) -> #N/A | S69: =P69*R69 -> #N/A | T69: =VLOOKUP(K69,'Inertia Bases 2025'!$A:$H,8,0) -> #N/A
A70: 98957962 | B70: TP 40-120/2 A-F-A-BQQE-DX1 | F70: 2697 | G70: =CEILING(F70*0.55,1) -> 1484 | R70: =VLOOKUP(N70,'Seismic Springs 2025'!$A:$I,9,0) -> #N/A | S70: =P70*R70 -> #N/A | T70: =VLOOKUP(K70,'Inertia Bases 2025'!$A:$H,8,0) -> #N/A
A71: 98957977 | B71: TP 50-60/2 A-F-A-BQQE-DX1 | F71: 2699 | G71: =CEILING(F71*0.55,1) -> 1485 | R71: =VLOOKUP(N71,'Seismic Springs 2025'!$A:$I,9,0) -> #N/A | S71: =P71*R71 -> #N/A | T71: =VLOOKUP(K71,'Inertia Bases 2025'!$A:$H,8,0) -> #N/A
...

Sheet Co-Efficients
A1: 0 | B1: 0.0001308042 | H1: 0 | I1: 0.00013 | K1: Preset charge (Pi) | L1: 150 | N1: Max Charge (Pf) | O1: 400
A2: 1 | B2: 7.2195408e-05 | H2: 10 | I2: 0.00025 | L2: 200 | O2: 500
A3: 2 | B3: 3.0149188e-05 | H3: 20 | I3: 0.00172 | L3: 250 | O3: 600
A4: 3 | B4: 4.291046e-06 | H4: 30 | I4: 0.0043 | O4: 1000
A5: 4 | B5: -5.74398e-06 | H5: 40 | I5: 0.0078
A6: 5 | B6: -3.11444e-07 | H6: 50 | I6: 0.01209
A7: 6 | B7: 2.0242388e-05 | H7: 60 | I7: 0.01711
A8: 7 | B8: 5.5580418e-05 | H8: 70 | I8: 0.02282
A9: 8 | B9: 0.0001053746 | H9: 80 | I9: 0.02921
A10: 9 | B10: 0.0001693058 | H10: 90 | I10: 0.0363
A11: 10 | B11: 0.00024706372 | H11: 100 | I11: 0.04408
A12: 11 | B12: 0.00033834672
A13: 12 | B13: 0.00044286175
A14: 13 | B14: 0.0005603242
A15: 14 | B15: 0.00069045778
A16: 15 | B16: 0.00083299443
A17: 16 | B17: 0.00098767415
A18: 17 | B18: 0.0011542449
A19: 18 | B19: 0.0013324626
A20: 19 | B20: 0.0015220907
A21: 20 | B21: 0.0017229004
A22: 21 | B22: 0.0019346704
A23: 22 | B23: 0.0021571867
... A101: 100 | B101: 0.044026533

Sheet UPS Pricing
A1: P/N | B1: DESCRIPTION | C1: 2024 MPG | D1: List Price | E1: Nett
A2: 519806 | B2: Union valve set G11/2"x1" | C2: AD | D2: 78 | E2: 50.7
A3: 529922 | B3: UNION SET G11/2"X1" CI | C3: AD | D3: 28 | E3: 18.2
A4: 529972 | B4: Union set G11/2"x1" | C4: AD | D4: 39 | E4: 25.35
A5: 59643600 | B5: UP20-30 N 150 1X240V 50HZ 9H | C5: DF | D5: 681 | E5: 374.55
A6: 91348548 | B6: DUAL UPS20-60 N 1X240V 50HZ STD | C6: DF | D6: 4622 | E6: 2542.1
A7: 91348640 | B7: DUAL UPS32-80 N 1X240V 50HZ DLX | C7: DF | D7: 7664 | E7: 4215.2
A8: 91348762 | B8: DUAL UPS20-60 N 1X240V 50HZ DLX | C8: DF | D8: 5889 | E8: 3238.95
A9: 91349121 | B9: DUAL UPS32-80 N 1X240V 50HZ STD | C9: DF | D9: 6321 | E9: 3476.55
A10: 93107332 | B10: UNION SET 11/4" 32MM BRASS | C10: AD | D10: 192 | E10: 124.8
A11: 93107333 | B11: UNION SET G11/2"X1" | C11: AD | D11: 40 | E11: 26
A12: 93107335 | B12: UNION SET BRASS 3/4' | C12: AD | D12: 92 | E12: 59.8
A13: 93108132 | B13: UNION VALVE SET 3/4-5/4" | C13: AD | D13: 87 | E13: 56.55
... A82: 99726692 | B82: HWC- DUAL MAGNA3 32-120 N 1x230V 50Hz | C82: BB | D82: 13992 | E82: 6996

Sheet Costing Template
A1: Reference | B1: SKU | C1: Name | D1: Qty | E1: Unit Nett | F1: IP-56 Nett | G1: Support Bar SKU | H1: Support Bar Nett (x2) | I1: Spring SKU | J1: Seismic Spring (x4) | K1: DT nett | L1: Unit Cost | M1: Total Cost | N1: Unit Sell | O1: Total Sell | P1: Margin | Q1: 0.815

Sheet NK Pricing
A1: SKU | B1: Name | C1: Quote # | D1: Quote Name | E1: Quote Date | F1: DT | G1: IP Rating | H1: Unit | I1: Base | J1: Springs | K1: Spring QTY | L1: Total Cost | M1: Sell Price | N1: Margin
A2: 93055672 | B2: NK 125-180/166 | C2: 1007528826 | D2: Sydney Biomedical Accelerator | E2: 45436 | F2: Y | H2: 6346.96 | I2: 643.75 | J2: 148.75 | K2: 4 | L2: 7585.71 | M2: =L2/$N$2 -> 9307.6196 | N2: 0.815 | O2: 5331.255
C3: 1007528826 | D3: Sydney Biomedical Accelerator | E3: 45436 | F3: N | H3: 6000.39 | I3: 643.75 | J3: 148.75 | K3: 4 | L3: 7239.14 | M3: =L3/$N$2 -> 8882.3804
C4: 1007364439 | D4: Ipswich Hospital | E4: 45363 | F4: Y | H4: 5740.86 | I4: 643.75 | J4: 148.75 | K4: 4 | L4: 6979.61 | M4: =L4/$N$2 -> 8563.9387
C5: 1007903185 | D5: Baxter Chilled Water Upgrade | E5: 45609 | F5: Y | H5: 5768.25 | I5: 656.56 | J5: 133.25 | K5: 4 | L5: =(K5*J5)+H5+I5 -> 6957.81 | M5: =L5/$N$2 -> 8537.1902
A6: 92775911 | B6: NK 100-180/167 | C6: 1007528826 | D6: Sydney Biomedical Accelerator | E6: 45436 | F6: N | H6: 5188.49 | I6: 628.75 | J6: 57.75 | K6: 4 | L6: 6048.24 | M6: =L6/$N$2 -> 7421.1534 | O6: 4522.915
C7: 1007395137 | D7: Noosa Hotel | E7: 45376 | F7: N | H7: 5073 | I7: 1000 | J7: 131.25 | K7: 6 | L7: 6860.5 | M7: =L7/$N$2 -> 8417.7914
A8: 92776056 | B8: NK 150-380/350 | C8: 1007528826 | D8: Sydney Biomedical Accelerator | E8: 45436 | F8: Y | H8: 16279.93 | I8: 1050 | J8: 148.75 | K8: 4 | L8: 17924.93 | M8: =L8/$N$2 -> 21993.779 | O8: 12566.255
C9: 1007377895 | D9: Westfield Parramatta | E9: 45369 | F9: N | H9: 14324.2 | I9: 1050 | J9: 148.75 | K9: 6 | L9: 16266.7 | M9: =L9/$N$2 -> 19959.141
C10: 1007320496 | D10: Redcliffe Hospital | E10: 45344 | F10: Y | H10: 16029.26 | I10: 1050 | J10: 148.75 | K10: 6 | L10: 17971.76 | M10: =L10/$N$2 -> 22051.239
C11: 1007589574 | D11: TPCH | E11: 45463 | F11: Y | H11: 15791.07 | I11: 1050 | J11: 148.75 | K11: 4 | L11: 17436.07 | M11: =L11/$N$2 -> 21393.951
C12: 1007816507 | D12: MEL12 | E12: 45569 | F12: N | H12: 14741.2 | I12: 1301.95 | J12: 151.71 | K12: 4 | L12: =(K12*J12)+H12+I12 -> 16649.99 | M12: =L12/$N$2 -> 20429.436
A13: 92775845 | B13: NK 65-225/232 | C13: 1007528826 | D13: Sydney Biomedical Accelerator | E13: 45436 | F13: N | H13: 6059.46 | I13: 650 | J13: 148.75 | K13: 4 | L13: 7304.46 | M13: =L13/$N$2 -> 8962.5276 | O13: 5421.16
C14: 1007395137 | D14: Noosa Hotel | E14: 45376 | F14: Y | H14: 6624.47 | I14: 1000 | J14: 131.25 | K14: 6 | L14: 8411.97 | M14: =L14/$N$2 -> 10321.436
A15: 92775868 | B15: NK 80-180/172 | C15: 1007528826 | D15: Sydney Biomedical Accelerator | E15: 45436 | F15: Y | H15: 4518.3 | I15: 636.25 | J15: 57.75 | K15: 4 | L15: 5385.55 | M15: =L15/$N$2 -> 6608.0368 | O15: 3548.845
C16: 1007394704 | D16: Bundaberg Hospital | E16: 45376 | F16: N | H16: 3698.65 | I16: 623.75 | J16: 57.75 | K16: 4 | L16: 4553.4 | M16: =L16/$N$2 -> 5586.9939
C17: 1008060801 | D17: TRI Stage 2 | E17: 45692 | F17: Y | G17: 55 | H17: 4253.54 | I17: 648.92 | J17: 133.86 | K17: 4 | L17: =(K17*J17)+H17+I17 -> 5437.9 | M17: =L17/$N$2 -> 6672.2699
C18: 1008060993 | D18: TRI Stage 2 | E18: 45692 | F18: Y | G18: 56 | H18: 4335.06 | I18: 648.92 | J18: 133.86 | K18: 4 | L18: =(K18*J18)+H18+I18 -> 5519.42 | M18: =L18/$N$2 -> 6772.2945
A19: 92775925 | B19: NK 100-225/215 | C19: 1007541813 | D19: Towoomba Hospital | E19: 45442 | F19: N | H19: 10928.7 | I19: 800 | J19: 148.75 | K19: 4 | L19: 12323.7 | M19: =L19/$N$2 -> 15121.104 | O19: 8852.49
C20: 1007394704 | D20: Bundaberg Hospital | E20: 45376 | F20: Y | H20: 11737.29 | I20: 800 | J20: 148.75 | K20: 4 | L20: 13132.29 | M20: =L20/$N$2 -> 16113.239
A21: 92776315 | B21: NK 125-380/405 | C21: 1007433753 | D21: 899 Collins St | E21: 45393 | F21: N | H21: 17071.12 | I21: 1010 | J21: 148.75 | K21: 6 | L21: 18973.62 | M21: =L21/$N$2 -> 23280.515 | O21: 11869.91
C22: 1007463845 | D22: Logan Hospital | E22: 45406 | F22: Y | H22: 15338.89 | I22: 1050 | J22: 148.75 | K22: 6 | L22: 17281.39 | M22: =L22/$N$2 -> 21204.16
C23: 1007586374 | D23: D&C Hospital Brisbane | E23: 45462 | F23: Y | H23: 15016.86 | I23: 1050 | J23: 57.75 | K23: 4 | L23: 16297.86 | M23: =L23/$N$2 -> 19997.374
A24: 92775926 | B24: NK 100-225/197 | C24: 1007589574 | D24: TPCH | E24: 45463 | F24: Y | H24: 10722.23 | I24: 755 | J24: 148.75 | K24: 4 | L24: 12072.23 | M24: =L24/$N$2 -> 14812.552 | O24: 8235.485
C25: 1007423760 | D25: QUT | E25: 45390 | F25: N | H25: 12552.44 | I25: 781.5 | J25: 148.75 | K25: 4 | L25: 13928.94 | M25: =L25/$N$2 -> 17090.724
A26: 92776317 | B26: NK 125-380/360 | C26: 1007589574 | D26: TPCH | E26: 45463 | F26: N | H26: 13457.4 | I26: 755 | J26: 148.75 | K26: 4 | L26: 14807.4 | M26: =L26/$N$2 -> 18168.589 | O26: 11265.66
C27: 1007595706 | D27: QEII | E27: 45467 | F27: N | H27: 13344.71 | I27: 791 | J27: 148.75 | K27: 4 | L27: 14730.71 | M27: =L27/$N$2 -> 18074.491
A28: 92775867 | B28: NK 80-180/174 | C28: 1007423760 | D28: QUT | E28: 45390 | F28: N | H28: 4821.56 | I28: 629 | J28: 148.75 | K28: 4 | L28: 6045.56 | M28: =L28/$N$2 -> 7417.865 | O28: 4169.18
C29: 1007528826 | D29: Sydney Biomedical Accelerator | E29: 45436 | F29: N | H29: 4818.76 | I29: 636.25 | J29: 57.75 | K29: 4 | L29: 5686.01 | M29: =L29/$N$2 -> 6976.6994
C30: 1007595706 | D30: QEII | E30: 45467 | F30: Y | H30: 4517.12 | I30: 791 | J30: 148.75 | K30: 4 | L30: 5903.12 | M30: =L30/$N$2 -> 7243.092
C31: 1008060801 | D31: TRI Stage 2 | E31: 45692 | F31: Y | G31: 55 | H31: 4910.44 | I31: 520.16 | J31: 133.86 | K31: 4 | L31: =(K31*J31)+H31+I31 -> 5966.04 | M31: =L31/$N$2 -> 7320.2945
C32: 1008060801 | D32: TRI Stage 2 | E32: 45692 | F32: Y | G32: 56 | H32: 4991.96 | I32: 520.16 | J32: 133.86 | K32: 4 | L32: =(K32*J32)+H32+I32 -> 6047.56 | M32: =L32/$N$2 -> 7420.319
A33: 92775927 | B33: NK 100-225/185 | C33: 1007528826 | D33: Sydney Biomedical Accelerator | E33: 45436 | F33: N | H33: 6945.71 | I33: 677.5 | J33: 148.75 | K33: 4 | L33: 8218.21 | M33: =L33/$N$2 -> 10083.693 | O33: 6211.61
C34: 1007595706 | D34: QEII | E34: 45467 | F34: Y | H34: 6826.14 | I34: 791 | J34: 148.75 | K34: 4 | L34: 8212.14 | M34: =L34/$N$2 -> 10076.245
C35: 1007423760 | D35: QUT | E35: 45390 | F35: N | H35: 6949.75 | I35: 677.5 | J35: 148.75 | K35: 4 | L35: 8222.25 | M35: =L35/$N$2 -> 10088.65
A36: 92775946 | B36: NK 100-350/326 | C36: 1007595706 | D36: QEII | E36: 45467 | F36: N | H36: 6253.88 | I36: 791 | J36: 148.75 | K36: 4 | L36: 7639.88 | M36: =L36/$N$2 -> 9374.0859 | O36: 6067
C37: 1007687288 | D37: Redcliffe Hospital | E37: 45509 | F37: N | H37: 6253.88 | I37: 982.46 | J37: 152.03 | K37: 4 | L37: =(K37*J37)+H37+I37 -> 7844.46 | M37: =L37/$N$2 -> 9625.1043
A38: 93055792 | B38: NK 200-300/288 | C38: 1007687288 | D38: Redcliffe Hospital | E38: 45509 | F38: N | H38: 13018.15 | I38: 817.64 | J38: 152.03 | K38: 4 | L38: =(K38*J38)+H38+I38 -> 14443.91 | M38: =L38/$N$2 -> 17722.589 | O38: 10919.31
A39: 93055858 | B39: NK 200-350/260 | C39: 1007687288 | D39: Redcliffe Hospital | E39: 45509 | F39: y | H39: 11295.36 | I39: 817.64 | J39: 152.03 | K39: 4 | L39: =(K39*J39)+H39+I39 -> 12721.12 | M39: =L39/$N$2 -> 15608.736 | O39: 10374.57
